# 异常
#### 1. 异常的传播，协程构建器有两种形式：自动传播异常（launch与actor）或向用户暴露异常（async与produce）
```
import kotlinx.coroutines.*

fun main() = runBlocking { 
	val job = GlobalScope.launch { // launch 根协程 
	println("Throwing exception from launch") throw IndexOutOfBoundsException() // 我们将在控制台打印 Thread.defaultUncaughtExceptionHandler
	}
	job.join() 
	println("Joined failed job") 
	val deferred = GlobalScope.async { // async 根协程 
		println("Throwing exception from async") 
		throw ArithmeticException() // 没有打印任何东西，依赖⽤⼾去调⽤等待 
		} 
		try {
			deferred.await()
			println("Unreached") 
		} catch (e: ArithmeticException) { 
			println("Caught ArithmeticException") 
		}

}
输出如下
Throwing exception from launch 
Exception in thread "DefaultDispatcher-worker-2 @coroutine#2" 
java.lang.IndexOutOfBoundsException
Joined failed job
Throwing exception from async 
Caught ArithmeticException
```
#### 2. 当⼀个协程使⽤ Job.cancel 取消的时候，它会被终⽌，但是它不会取消它的⽗协程。如果⼀个协程遇到了 CancellationException 以外的异常，它将使⽤该异常取消它的⽗协程
#### 3. 异常聚合：当协程的多个⼦协程因异常⽽失败时，⼀般规则是“取第⼀个异常”，因此将处理第⼀个异常。在第⼀个异常之后 发⽣的所有其他异常都作为被抑制的异常绑定⾄第⼀个异常。
