# 异常
#### 1. 异常的传播，协程构建器有两种形式：自动传播异常（launch与actor）或向用户暴露异常（async与produce）
```
import kotlinx.coroutines.*

fun main() = runBlocking { 
	val job = GlobalScope.launch { // launch 根协程 
	println("Throwing exception from launch") throw IndexOutOfBoundsException() // 我们将在控制台打印 Thread.defaultUncaughtExceptionHandler
	}
	job.join() 
	println("Joined failed job") 
	val deferred = GlobalScope.async { // async 根协程 
		println("Throwing exception from async") 
		throw ArithmeticException() // 没有打印任何东西，依赖⽤⼾去调⽤等待 
		} 
		try {
			deferred.await()
			println("Unreached") 
		} catch (e: ArithmeticException) { 
			println("Caught ArithmeticException") 
		}

}
输出如下
Throwing exception from launch 
Exception in thread "DefaultDispatcher-worker-2 @coroutine#2" 
java.lang.IndexOutOfBoundsException
Joined failed job
Throwing exception from async 
Caught ArithmeticException
```
